{
  "comments": [
    {
      "key": {
        "uuid": "74f1fb1d_4d7d1f48",
        "filename": "lib/includes/Store/Sql/Terms/DatabaseItemTermStore.php",
        "patchSetId": 2
      },
      "lineNbr": 108,
      "author": {
        "id": 6768
      },
      "writtenOn": "2019-06-04T10:41:09Z",
      "side": 1,
      "message": "Should we catch all exceptions here and not just DBError, to rollback in all cases?",
      "revId": "7d00348d23d67cfc7a94ff40439e513ddb99d153",
      "serverId": "e9e9afe9-4712-486d-8885-f54b72dd1951",
      "unresolved": true
    },
    {
      "key": {
        "uuid": "6551bf43_75441109",
        "filename": "lib/includes/Store/Sql/Terms/DatabaseItemTermStore.php",
        "patchSetId": 2
      },
      "lineNbr": 108,
      "author": {
        "id": 4699
      },
      "writtenOn": "2019-06-04T10:45:50Z",
      "side": 1,
      "message": "I’m not sure… I guess it would be safe to do, because we re-throw the exception at the end, even if it’s something totally unexpected.",
      "parentUuid": "74f1fb1d_4d7d1f48",
      "revId": "7d00348d23d67cfc7a94ff40439e513ddb99d153",
      "serverId": "e9e9afe9-4712-486d-8885-f54b72dd1951",
      "unresolved": true
    },
    {
      "key": {
        "uuid": "06ab2dcb_9b24d16d",
        "filename": "lib/includes/Store/Sql/Terms/DatabaseItemTermStore.php",
        "patchSetId": 2
      },
      "lineNbr": 108,
      "author": {
        "id": 16
      },
      "writtenOn": "2019-06-04T18:27:48Z",
      "side": 1,
      "message": "How does this work without getting errors from assertTransactionRoundStage() ?",
      "parentUuid": "6551bf43_75441109",
      "revId": "7d00348d23d67cfc7a94ff40439e513ddb99d153",
      "serverId": "e9e9afe9-4712-486d-8885-f54b72dd1951",
      "unresolved": true
    }
  ]
}